<?xml version="1.0"?>
<robot name="ur5" xmlns:xacro="http://wiki.ros.org/xacro">

    <xacro:macro name="cylinder_i" params="radius length mass *origin">
        <inertial>
            <mass value="${mass}" />
            <xacro:insert_block name="origin" />
            <inertia ixx="${0.0833333 * mass * (3 * radius * radius + length * length)}" ixy="0.0" ixz="0"
                     iyy="${0.0833333 * mass * (3 * radius * radius + length * length)}" iyz="0.0"
                     izz="${0.5 * mass * radius * radius}" />
        </inertial>
    </xacro:macro>

    <!-- <kinematic Joint -->
    <joint name="world_joint" type="fixed">
        <origin xyz="0.0 0.0 0.0" rpy="0.0 0.0 0.0"/>
        <parent link="world"/>
        <child link="base_link"/>
    </joint>

    <joint name="shoulder_1_joint" type="continuous">
        <origin xyz="0.0 0.0 0.089159" rpy="0.0 0.0 0.0"/>
        <parent link="base_link"/>
        <child link="shoulder_link"/>
        <axis xyz="0.0 0.0 1.0"/>
        <!-- <limit lower="-"    
               upper="${shoulder_pan_upper_limit}"
               effort="${shoulder_pan_effort_limit}" 
               velocity="${shoulder_pan_velocity_limit}"/> -->
    </joint>

    <joint name="shoulder_2_joint" type="continuous">
        <origin xyz="0.0 0.13585 0.0" rpy="0.0 1.570796325 0.0"/>
        <parent link="shoulder_link"/>
        <child link="upper_arm_link"/>
        <axis xyz="0.0 1.0 0.0"/>
    </joint>

    <joint name="elbow_joint" type="continuous">

        <origin xyz="0.0 -0.1197 0.425" rpy="0.0 0.0 0.0"/>
        <parent link="upper_arm_link"/>
        <child link="forearm_link"/>
        <axis xyz="0.0 1.0 0.0"/>
    </joint>

    <joint name="wrist_1_joint" type="continuous">
        <origin xyz="0.0 0 0.39225" rpy="0.0 1.570796325 0.0"/>
        <parent link="forearm_link"/>
        <child link="wrist_1_link"/>
        <axis xyz="0.0 1.0 0.0"/>
    </joint>

    <joint name="wrist_2_joint" type="continuous">
        <origin xyz="0.0 0.093 0.0" rpy="0.0 0.0 0.0"/>
        <parent link="wrist_1_link"/>
        <child link="wrist_2_link"/>
        <axis xyz="0.0 0.0 1.0"/>
    </joint>

    <joint name="wrist_3_joint" type="continuous">
        <origin xyz="0 0 0.09465" rpy="0.0 0.0 0.0"/>
        <parent link="wrist_2_link"/>
        <child link="wrist_3_link"/>
        <axis xyz="0.0 1.0 0.0"/>
    </joint>

    <!-- Link interia-->
    <link name="world"/>
    <link name="base_link">
        <xacro:cylinder_i radius='0.06' length='0.05' mass='4.0'> 
            <origin xyz="0.0 0.0 0.0" rpy="0.0 0.0 0.0"/>
        </xacro:cylinder_i>
        <visual>
            <geometry>
                <mesh filename="package://mr_pkg/meshes/ur5/visual/base.dae"/>
            </geometry>
            <material name='LightGrey'>
               <color rgba="0.7 0.7 0.7 1.0"/>
            </material>
        </visual>
    </link>

    <link name="shoulder_link">
        <xacro:cylinder_i radius='0.075' length='0.178' mass='3.7'> 
            <origin xyz="0.0 0.0 0.0" rpy="0.0 0.0 0.0"/>
        </xacro:cylinder_i>
        <visual>
            <geometry>
                <mesh filename="package://mr_pkg/meshes/ur5/visual/shoulder.dae"/>
            </geometry>
            <material name='LightGrey'>
               <color rgba="0.7 0.7 0.7 1.0"/>
            </material>
        </visual>
    </link>

    <link name="upper_arm_link">
        <xacro:cylinder_i radius='0.06' length='0.425' mass='8.3930'> 
            <origin xyz="0.0 0.0 0.0" rpy="0.0 0.0 0.0"/>
        </xacro:cylinder_i>
        <visual>
            <origin xyz="0.0 0.0 0.0" rpy="0.0 0.0 0.0" />
            <geometry>
                <mesh filename="package://mr_pkg/meshes/ur5/visual/upperarm.dae"/>
            </geometry>
            <material name='LightGrey'>
               <color rgba="0.7 0.7 0.7 1.0"/>
            </material>
        </visual>
    </link>

    <link name="forearm_link">
        <xacro:cylinder_i radius='0.06' length='0.39225' mass='2.2750'> 
            <origin xyz="0.0 0.0 0.0" rpy="0.0 0.0 0.0"/>
        </xacro:cylinder_i>
        <visual>
            <origin xyz="0 0 0" rpy="0 0 0"/>
            <geometry>
                <mesh filename="package://mr_pkg/meshes/ur5/visual/forearm.dae"/>
            </geometry>
            <material name='LightGrey'>
               <color rgba="0.7 0.7 0.7 1.0"/>
            </material>
        </visual>
    </link>

    <link name="wrist_1_link">
        <xacro:cylinder_i radius='0.06' length='0.12' mass='1.2190'> 
            <origin xyz="0.0 0.0 0.0" rpy="0.0 0.0 0.0"/>
        </xacro:cylinder_i>
        <visual>
            <origin xyz="0 0 0" rpy="0 0 0"/>
            <geometry>
                <mesh filename="package://mr_pkg/meshes/ur5/visual/wrist1.dae"/>
            </geometry>
            <material name='LightGrey'>
               <color rgba="0.7 0.7 0.7 1.0"/>
            </material>
        </visual>
    </link>

    <link name="wrist_2_link">
        <xacro:cylinder_i radius='0.06' length='0.12' mass='1.2190'> 
            <origin xyz="0.0 0.0 0.0" rpy="0.0 0.0 0.0"/>
        </xacro:cylinder_i>
        <visual>
            <origin xyz="0 0 0" rpy="0 0 0"/>
            <geometry>
                <mesh filename="package://mr_pkg/meshes/ur5/visual/wrist2.dae"/>
            </geometry>
            <material name='LightGrey'>
               <color rgba="0.7 0.7 0.7 1.0"/>
            </material>
        </visual>
    </link>

    <link name="wrist_3_link">
        <xacro:cylinder_i radius='0.0375' length='0.0345' mass='0.1879'> 
            <origin xyz="0.0 0.0 0.0" rpy="0.0 0.0 0.0"/>
        </xacro:cylinder_i>
        <visual>
            <origin xyz="0 0 0" rpy="0 0 0"/>
            <geometry>
                <mesh filename="package://mr_pkg/meshes/ur5/visual/wrist3.dae"/>
            </geometry>
            <material name='LightGrey'>
               <color rgba="0.7 0.7 0.7 1.0"/>
            </material>
        </visual>
    </link>

    <!-- ee -->
    <link name="ee_link"/>
    <joint name="ee_joint" type="fixed">
        <origin xyz="0.0 0.082 0.0" rpy="-1.570796325 0.0 0.0"/>
        <parent link="wrist_3_link"/>
        <child link="ee_link"/>
    </joint>

</robot>